Workbook

Sheet weerhouden waarde
A1: [NAAM VENNOOTSCHAP]
A2: [straat + nummer]
A3: [postcode + gemeente]
A4: ON. [ondernemingsnummer]
A6: Toestand op [afsluitdatum] (afsluitdatum)
A8: WEERHOUDEN WAARDE
A10: Rekening houdende met de aard en de activiteiten van de vennootschap, zijnde [omschrijving activiteit], worden ter bepaling van de waarde van de aandelen van de in rand vermelde vennootschap, navolgende methoden toegepast :
A15: - Een substantiële waardebepaling
A16: - Een rendementswaarde berekening
A17: - Een berekening naar de waarde op basis van de EBITDA (marktwaarde)
A18: - Een berekening naar de waarde op basis van de DCF-methode
A20: De substantiële waarde wordt bekomen op basis van het eigen vermogen van de vennootschap. De eigen vermogenswaarde wordt gecorrigeerd met de latente min- en/of meerwaarden die op de activa en passiva aanwezig zijn. Hieraan wordt de waarde van de goodwill, berekend op basis van de verwachte recurrente inkomsten- en uitgavenstromen, toegevoegd.
... A68: van de in rand vermelde vennootschap weerhouden worden :
A75: Substantiële waarde | B75: ='substantiële waarde'!C14 -> 0 | C75: x 1/3 | D75: =B75*1/3 -> 0
A76: Rendementswaarde | B76: =Rendementswaarde!C15 -> 0 | C76: x 1/3 | D76: =B76*1/3 -> 0
A77: Marktwaarde (EBITDA) | B77: ='Marktwaarde '!D27 -> 0 | C77: x 1/3 | D77: =B77*1/3 -> 0
A78: DCF waarde | B78: 0 | C78: x 1/4 | D78: =B78*1/4 -> 0
A80: ="Waarde 100% aandelen "&A1 -> Waarde 100% aandelen [NAAM VENNOOTSCHAP] | D80: =SUM(D75:D77) -> 0
A82: afgerond = | D82: =ROUND(D80,-3) -> 0
A91: 3. Een voorbehoud omtrent de bodemtoestand van het onroerend en de eventuele aanwezigheid van asbest,
A92: aangezien ons hieromtrent geen verdere informatie beschikbaar is.
A95: PM
A97: 1. Er worden verondersteld geen hangende geschillen (met overheidsdiensten, fiscus, derden,…) e.d. te zijn met een van materiële aarde zijnde negatieve impact voor de vennootschap.
A100: 2. De gebruikte historische cijfers zijn geen geauditeerde cijfers.
A102: 3. Er wordt geen rekening gehouden met de eigen vermogensevolutie na [afsluitdatum].
B159: (6) en (7) financiële opbrengsten/kosten op overtollige activa/passiva worden hier geannuleerd, net als positieve/negatieve wisselkoersverschillen

Sheet Swot
B1: ="SWOT analyse voor bepaling waarde aandelen "&'weerhouden waarde'!A1 -> SWOT analyse voor bepaling waarde aandelen [NAAM VENNOOTSCHAP]
B4: STERKTES | D4: ZWAKTES
B18: OPPORTUNITEITEN | D18: BEDREIGINGEN

Sheet substantiële waarde
A1: ='weerhouden waarde'!A1 -> [NAAM VENNOOTSCHAP]
A4: ='weerhouden waarde'!A6 -> Toestand op [afsluitdatum] (afsluitdatum)
A7: SUBSTANTIËLE WAARDE
A10: gecorrigeerd eigen vermogen | B10: =ROUND('gecorrigeerd eigen vermogen'!E44,-3) -> 0
A11: goodwill | B11: =Goodwill!D22 -> 0
A14: Substantiële waarde | C14: =B11+B10 -> 0

Sheet gecorrigeerd eigen vermogen
A1: ='weerhouden waarde'!A1 -> [NAAM VENNOOTSCHAP]
A4: ='weerhouden waarde'!A6 -> Toestand op [afsluitdatum] (afsluitdatum)
A7: GECORRIGEERD EIGEN VERMOGEN
A9: eigen vermogen | E9: =SUM(D11:D13) -> 0
A11: Beschikbare inbreng buiten kapitaal
A12: Beschikbare reserves - liquidatiereserves
A13: Overgedragen winst
A15: correcties op eigen vermogen | E15: =SUM(D17:D19) -> 0
A17: latente meerwaarde onroerende goederen (zie detail meerw. MVA) | D17: =MVA!M33 -> 0
A18: latente meerwaarde roerende goederen (zie detail meerw. MVA) | D18: =MVA!M114 -> 0
A19: latente minderwaarde handelsvorderingen (3) | D19: 0
A21: latentie vennootschapsbelasting | E21: =-D26 -> 0
A24: =A18 -> latente meerwaarde roerende goederen (zie detail meerw. MVA) | D24: =D18 -> 0
D25: =SUM(D24:D24) -> 0
B26: (1) | C26: =D60 -> 0.19024739 | D26: =D25*C26 -> 0
A28: =A19 -> latente minderwaarde handelsvorderingen (3) | D28: =D19 -> 0
D29: =D28 -> 0
C30: 0.125 | D30: =D29*C30 -> 0
A33: Latentie liquidatiebelasting op gecorr EV - kapitaal | E33: =-D39 -> 0
A34: =A12 -> Beschikbare reserves - liquidatiereserves | D34: =D12 -> 0
A35: =A13 -> Overgedragen winst | D35: =D13 -> 0
A36: correcties op eigen vermogen | D36: =E15 -> 0
A37: belastingslatentie op correcties eigen vermogen | D37: =E21 -> 0
D38: =SUM(D34:D37) -> 0
B39: (2) | C39: 0 | D39: =D38*C39 -> 0
A44: Gecorrigeerd eigen vermogen | E44: =SUM(E7:E42) -> 0
A47: (1) : Inbreng | B47: Inbreng [datum oprichting / omschrijving]
C48: =SUM(C47:C47) -> 0 | D48: =SUM(D47:D47) -> 0
A50: (1) : latentie vennootschapsbelasting :
A51: Het tarief van de latente vennootschapsbelasting wordt berekend uitgaande van het vigerend tarief in de vennootschapsbelasting (ad 25%) waarbij een actualisatie wordt doorgevoerd voor een periode van 10 jaar aan een jaarlijkse verdisconteringsfactor dewelke overeenstemt met de gemiddelde OLO van de laatste 20 jaar
D56: 10 jaar
B57: - toepasselijk tarief vennootschapsbelasting | D57: 0.25
B58: - gemiddelde OLO rentevoet van laatste 20 jaar | D58: =+OLO!G49 -> 0.02769
B59: - toepasselijke verdisconteringscoëfficiënt | D59: =1/(1+D58)^10 -> 0.76098955
B60: - tarief latente vennootschapsbelasting | D60: =D57*D59 -> 0.19024739
A62: (2) : latentie liquidatiebelastingen :
A63: We gaan in onderhavige waardering uit van het scenario dat de aandelen in de toekomst worden aangehouden door een holdingvennootschap. Aldus wordt geen latente liquidatiebelasting weerhouden.
A66: (3) : latentie minderwaarde handelsvorderingen :
A67: Op basis van het detail van de openstaande klanten d.d. [datum] [besluit over achterstallige saldi]. We weerhouden aldus [geen] latente minderwaarde op de openstaande handelsvorderingen per [afsluitdatum].
A112: (4): Nihil wegens vennootschapsaandeelhouders

Sheet MVA
A1: ='weerhouden waarde'!A1 -> [NAAM VENNOOTSCHAP]
A4: ='weerhouden waarde'!A6 -> Toestand op [afsluitdatum] (afsluitdatum)
B6: WAARDERING MATERIËLE VASTE ACTIVA
A9: datum | B9: jaar | C9: omschrijving | D9: AW | E9: restwaarde | F9: af te schrijven | G9: # jaar | H9: afgeschr. | I9: afschrijvingen | J9: berekende BW | K9: weerhouden w. | L9: BW klant | M9: latente mw | N9: Vervangingsinvest.
C11: ONROERENDE GOEDEREN
C13: Terreinen en gebouwen
C15: Bedrijfspand - [adres]
D30: =SUM(D16:D29) -> 0 | K30: =IF(D43="",L30,ROUND(D43,-3)) -> 0 | M30: =K30-L30 -> 0
C33: TOTAAL | D33: =D30 -> 0 | J33: (1) | K33: =K30 -> 0 | L33: =L30 -> 0 | M33: =K33-L33 -> 0
L35: Afgerond | M35: =ROUND(M33,-3) -> 0
B36: (1) | C36: Raming actuele venale waarde onroerend goed
C38: Marktwaarde cfr. schattingsverslag [schatter] | E38: (marktwaarde - vrij op naam)
C39: d.d. [datum schattingsverslag]
C41: Indexatie t.o.v. datum schattingsverslag (leeg = geen indexatie)
C43: Geindexeerde marktwaarde | D43: =IF(D38="","",D38*IF(D41="",1,D41))
C46: ROERENDE GOEDEREN
C48: Computers/hardware (#240100)
C49: 5 jaar met restwaarde = 0%
E50: =D50*0 -> 0 | F50: =D50-E50 -> 0 | G50: 5 | H50: =IF(B50="",G50,IF($H$7-B50>G50,G50,$H$7-B50)) -> 5 | I50: =F50/G50*H50 -> 0 | J50: =D50-I50 -> 0 | K50: =J50 -> 0
E51: =D51*0 -> 0 | F51: =D51-E51 -> 0 | G51: 5 | H51: =IF(B51="",G51,IF($H$7-B51>G51,G51,$H$7-B51)) -> 5 | I51: =F51/G51*H51 -> 0 | J51: =D51-I51 -> 0 | K51: =J51 -> 0
E52: =D52*0 -> 0 | F52: =D52-E52 -> 0 | G52: 5 | H52: =IF(B52="",G52,IF($H$7-B52>G52,G52,$H$7-B52)) -> 5 | I52: =F52/G52*H52 -> 0 | J52: =D52-I52 -> 0 | K52: =J52 -> 0
E53: =D53*0 -> 0 | F53: =D53-E53 -> 0 | G53: 5 | H53: =IF(B53="",G53,IF($H$7-B53>G53,G53,$H$7-B53)) -> 5 | I53: =F53/G53*H53 -> 0 | J53: =D53-I53 -> 0 | K53: =J53 -> 0
E54: =D54*0 -> 0 | F54: =D54-E54 -> 0 | G54: 5 | H54: =IF(B54="",G54,IF($H$7-B54>G54,G54,$H$7-B54)) -> 5 | I54: =F54/G54*H54 -> 0 | J54: =D54-I54 -> 0 | K54: =J54 -> 0
D55: =SUM(D50:D54) -> 0 | E55: =SUM(E50:E54) -> 0 | F55: =SUM(F50:F54) -> 0 | I55: =SUM(I50:I54) -> 0 | J55: =SUM(J50:J54) -> 0 | K55: =SUM(K50:K54) -> 0 | M55: =K55-L55 -> 0 | N55: =F55/G50 -> 0
C58: Installaties, machines en uitrusting (#230000)
C59: 7 jaar met een restwaarde van 10% (voor investeringen na 2018)
E60: =D60*IF(B60>2018,10%,0) -> 0 | F60: =D60-E60 -> 0 | G60: 7 | H60: =IF(B60="",G60,IF($H$7-B60>G60,G60,$H$7-B60)) -> 7 | I60: =F60/G60*H60 -> 0 | J60: =D60-I60 -> 0 | K60: =J60 -> 0
E61: =D61*IF(B61>2018,10%,0) -> 0 | F61: =D61-E61 -> 0 | G61: 7 | H61: =IF(B61="",G61,IF($H$7-B61>G61,G61,$H$7-B61)) -> 7 | I61: =F61/G61*H61 -> 0 | J61: =D61-I61 -> 0 | K61: =J61 -> 0
E62: =D62*IF(B62>2018,10%,0) -> 0 | F62: =D62-E62 -> 0 | G62: 7 | H62: =IF(B62="",G62,IF($H$7-B62>G62,G62,$H$7-B62)) -> 7 | I62: =F62/G62*H62 -> 0 | J62: =D62-I62 -> 0 | K62: =J62 -> 0
E63: =D63*IF(B63>2018,10%,0) -> 0 | F63: =D63-E63 -> 0 | G63: 7 | H63: =IF(B63="",G63,IF($H$7-B63>G63,G63,$H$7-B63)) -> 7 | I63: =F63/G63*H63 -> 0 | J63: =D63-I63 -> 0 | K63: =J63 -> 0
E64: =D64*IF(B64>2018,10%,0) -> 0 | F64: =D64-E64 -> 0 | G64: 7 | H64: =IF(B64="",G64,IF($H$7-B64>G64,G64,$H$7-B64)) -> 7 | I64: =F64/G64*H64 -> 0 | J64: =D64-I64 -> 0 | K64: =J64 -> 0
E65: =D65*IF(B65>2018,10%,0) -> 0 | F65: =D65-E65 -> 0 | G65: 7 | H65: =IF(B65="",G65,IF($H$7-B65>G65,G65,$H$7-B65)) -> 7 | I65: =F65/G65*H65 -> 0 | J65: =D65-I65 -> 0 | K65: =J65 -> 0
E66: =D66*IF(B66>2018,10%,0) -> 0 | F66: =D66-E66 -> 0 | G66: 7 | H66: =IF(B66="",G66,IF($H$7-B66>G66,G66,$H$7-B66)) -> 7 | I66: =F66/G66*H66 -> 0 | J66: =D66-I66 -> 0 | K66: =J66 -> 0
E67: =D67*IF(B67>2018,10%,0) -> 0 | F67: =D67-E67 -> 0 | G67: 7 | H67: =IF(B67="",G67,IF($H$7-B67>G67,G67,$H$7-B67)) -> 7 | I67: =F67/G67*H67 -> 0 | J67: =D67-I67 -> 0 | K67: =J67 -> 0
E68: =D68*IF(B68>2018,10%,0) -> 0 | F68: =D68-E68 -> 0 | G68: 7 | H68: =IF(B68="",G68,IF($H$7-B68>G68,G68,$H$7-B68)) -> 7 | I68: =F68/G68*H68 -> 0 | J68: =D68-I68 -> 0 | K68: =J68 -> 0
E69: =D69*IF(B69>2018,10%,0) -> 0 | F69: =D69-E69 -> 0 | G69: 7 | H69: =IF(B69="",G69,IF($H$7-B69>G69,G69,$H$7-B69)) -> 7 | I69: =F69/G69*H69 -> 0 | J69: =D69-I69 -> 0 | K69: =J69 -> 0
E70: =D70*IF(B70>2018,10%,0) -> 0 | F70: =D70-E70 -> 0 | G70: 7 | H70: =IF(B70="",G70,IF($H$7-B70>G70,G70,$H$7-B70)) -> 7 | I70: =F70/G70*H70 -> 0 | J70: =D70-I70 -> 0 | K70: =J70 -> 0
E71: =D71*IF(B71>2018,10%,0) -> 0 | F71: =D71-E71 -> 0 | G71: 7 | H71: =IF(B71="",G71,IF($H$7-B71>G71,G71,$H$7-B71)) -> 7 | I71: =F71/G71*H71 -> 0 | J71: =D71-I71 -> 0 | K71: =J71 -> 0
... E79: =D79*IF(B79>2018,10%,0) -> 0 | F79: =D79-E79 -> 0 | G79: 7 | H79: =IF(B79="",G79,IF($H$7-B79>G79,G79,$H$7-B79)) -> 7 | I79: =F79/G79*H79 -> 0 | J79: =D79-I79 -> 0 | K79: =J79 -> 0
D80: =SUM(D60:D79) -> 0 | E80: =SUM(E60:E79) -> 0 | F80: =SUM(F60:F79) -> 0 | I80: =SUM(I60:I79) -> 0 | J80: =SUM(J60:J79) -> 0 | K80: =SUM(K60:K79) -> 0 | M80: =K80-L80 -> 0 | N80: =F80/G60 -> 0
...

Sheet Goodwill
A1: ='weerhouden waarde'!A1 -> [NAAM VENNOOTSCHAP]
A3: ='gecorrigeerd eigen vermogen'!A4 -> Toestand op [afsluitdatum] (afsluitdatum)
A5: WAARDERING GOODWILL
B7: Gecorrigeerd eigen vermogen | D7: =ROUND('gecorrigeerd eigen vermogen'!E44,-3) -> 0
B9: Overtollige activa (3) | D9: =-E42 -> 0
B11: Geïnvesteerd risicokapitaal | D11: =D7+D9 -> 0
B12: Afgerond | D12: =IF(D11>0,CEILING(D11,1000),0) -> 0
B14: Gecorrigeerde vrije cash flow | D14: ='Gecorrigeerde vrije cash flow'!K76 -> 0
B16: vereist rendement op EV (1) | C16: =E31 -> 0
B17: aantal jaar goodwill (2) | C17: 7 | D17: jaar
B18: vereist risicoloos rendement (gemiddelde OLO 20 jaar + 1,5%) | C18: =+OLO!G49+1.5% -> 0.04269
B21: goodwill | D21: =(D14-D12*C16)/(C18+(100/C17)%) -> 0
B22: afgerond | D22: =ROUND(D21,-3) -> 0
A25: Het rendement op EV wordt bepaald op basis van de samenstelling van het actief :
B26: - O&O : | C26: 0.2 | D26: =E54 -> 0 | E26: =C26*D26 -> 0
B27: - materiële vaste activa : | C27: 0.12 | D27: =E55+E56 -> 0 | E27: =C27*D27 -> 0
B28: - voorraad : | C28: 0.1 | D28: =E59 -> 0 | E28: =C28*D28 -> 0
B29: - vorderingen : | C29: 0.08 | D29: =E67 -> 0 | E29: =C29*D29 -> 0
B30: - liquide middelen : | C30: 0.06 | D30: =E71 -> 0 | E30: =C30*D30 -> 0
D31: =SUM(D26:D30) -> 0 | E31: =SUM(E26:E30) -> 0
A33: 7 jaar wordt weerhouden omwille van :
B34: a) [motivering +] (+)
B35: b) [motivering +] (+)
B36: c) [motivering +] (+)
B37: d) [motivering +] (+)
B38: e) [motivering -] (-)
B39: f) [motivering -] (-)
A42: (3) Overtollige activa en passiva worden als volgt berekend (toestand per [afsluitdatum]): | E42: =SUM(D43:D49) -> 0
B44: Roerend vermogen
B45: Liquide middelen | D45: =D71 -> 0
B46: Terug te vorderen belastingen
B47: Te betalen vennootschapsbelasting
B48: R/C bestuurder
B49: Correctie financiering werkkapitaal | D49: =E118 -> 0 | E49: (*)
B51: BALANS | C51: CODE | D51: [afsluitdatum]
A53: 1. | B53: OPRICHTINGSKOSTEN | C53: 20
A54: 2. | B54: IMMATERIELE VASTE ACTIVA | C54: 21 | E54: =IFERROR(D54/D74,0) -> 0
A55: 3. | B55: MATERIELE VASTE ACTIVA | C55: 22/27 | E55: =IFERROR(D55/D74,0) -> 0
A56: 4. | B56: FINANCIELE VASTE ACTIVA | C56: 28 | E56: =IFERROR(D56/D74,0) -> 0
A57: 5. | B57: VORDERINGEN OP + 1 JAAR | C57: 29
...

Sheet Gecorrigeerde vrije cash flow
B1: ='gecorrigeerd eigen vermogen'!A1 -> [NAAM VENNOOTSCHAP]
B4: ='gecorrigeerd eigen vermogen'!A4 -> Toestand op [afsluitdatum] (afsluitdatum)
B7: GECORRIGEERDE VRIJE CASH FLOW | R7: Prognose
H10: (12 maanden) | K10: (12 maanden) | N10: (12 maanden) | R10: (12 maanden)
B11: Normalisatiefactor (12 / aantal maanden) | H11: 1 | K11: 1 | N11: 1 | R11: 1
B12: Omzet | H12: =SUM(H13:H18) -> 0 | K12: =SUM(K13:K18) -> 0 | N12: =SUM(N13:N18) -> 0 | R12: =SUM(R13:R18) -> 0
B13: Verkopen | I13: =IFERROR(H13/H$12,"") | L13: =IFERROR(K13/K$12,"") | O13: =IFERROR(N13/N$12,"") | S13: =IFERROR(R13/R$12,"")
B14: Export | I14: =IFERROR(H14/H$12,"") | L14: =IFERROR(K14/K$12,"") | O14: =IFERROR(N14/N$12,"") | S14: =IFERROR(R14/R$12,"")
B15: Commissie | I15: =IFERROR(H15/H$12,"") | L15: =IFERROR(K15/K$12,"") | O15: =IFERROR(N15/N$12,"") | S15: =IFERROR(R15/R$12,"")
B16: Cardetailing | I16: =IFERROR(H16/H$12,"") | L16: =IFERROR(K16/K$12,"") | O16: =IFERROR(N16/N$12,"") | S16: =IFERROR(R16/R$12,"")
B17: Verhuur | I17: =IFERROR(H17/H$12,"") | L17: =IFERROR(K17/K$12,"") | O17: =IFERROR(N17/N$12,"") | S17: =IFERROR(R17/R$12,"")
B18: Doorrekening | I18: =IFERROR(H18/H$12,"") | L18: =IFERROR(K18/K$12,"") | O18: =IFERROR(N18/N$12,"") | S18: =IFERROR(R18/R$12,"")
I19: =IFERROR(H19/H$12,"") | L19: =IFERROR(K19/K$12,"") | O19: =IFERROR(N19/N$12,"") | S19: =IFERROR(R19/R$12,"")
B20: - Aankopen | H20: =-SUM(H21:H24) -> 0 | I20: =IFERROR(H20/H$12,"") | K20: =-SUM(K21:K24) -> 0 | L20: =IFERROR(K20/K$12,"") | N20: =-SUM(N21:N24) -> 0 | O20: =IFERROR(N20/N$12,"") | R20: =-SUM(R21:R24) -> 0 | S20: =IFERROR(R20/R$12,"")
B21: Aankopen | I21: =IFERROR(-H21/H$20,"") | L21: =IFERROR(-K21/K$20,"") | O21: =IFERROR(-N21/N$20,"") | S21: =IFERROR(-R21/R$20,"")
B22: Onderaanneming | I22: =IFERROR(-H22/H$20,"") | L22: =IFERROR(-K22/K$20,"") | O22: =IFERROR(-N22/N$20,"") | S22: =IFERROR(-R22/R$20,"")
B23: Leasingkosten | I23: =IFERROR(-H23/H$20,"") | L23: =IFERROR(-K23/K$20,"") | O23: =IFERROR(-N23/N$20,"") | S23: =IFERROR(-R23/R$20,"")
B24: Vooraadwijziging (+/-) | I24: =IFERROR(-H24/H$20,"") | L24: =IFERROR(-K24/K$20,"") | O24: =IFERROR(-N24/N$20,"") | S24: =IFERROR(-R24/R$20,"")
B26: = Bruto marge | H26: =H12+H20 -> 0 | I26: =IFERROR(H26/H$12,"") | K26: =K12+K20 -> 0 | L26: =IFERROR(K26/K$12,"") | N26: =N12+N20 -> 0 | O26: =IFERROR(N26/N$12,"") | R26: =R12+R20 -> 0 | S26: =IFERROR(R26/R$12,"")
B28: - Transportkosten | I28: =IFERROR(H28/H$12,"") | L28: =IFERROR(K28/K$12,"") | O28: =IFERROR(N28/N$12,"") | S28: =IFERROR(R28/R$12,"")
B30: = Contributiemarge | H30: =H26+H28 -> 0 | I30: =IFERROR(H30/H$12,"") | K30: =K26+K28 -> 0 | L30: =IFERROR(K30/K$12,"") | N30: =N26+N28 -> 0 | O30: =IFERROR(N30/N$12,"") | R30: =R26+R28 -> 0 | S30: =IFERROR(R30/R$12,"")
B32: - Diensten en diverse goederen | H32: =SUM(H33:H39) -> 0 | I32: =IFERROR(H32/H$12,"") | K32: =SUM(K33:K39) -> 0 | L32: =IFERROR(K32/K$12,"") | N32: =SUM(N33:N39) -> 0 | O32: =IFERROR(N32/N$12,"") | R32: =SUM(R33:R39) -> 0 | S32: =IFERROR(R32/R$12,"")
B33: Huur (610) | I33: =IFERROR(H33/H$32,"") | L33: =IFERROR(K33/K$32,"") | O33: =IFERROR(N33/N$32,"") | S33: =IFERROR(R33/R$32,"")
B34: Kosten gebouw (611) | I34: =IFERROR(H34/H$32,"") | L34: =IFERROR(K34/K$32,"") | O34: =IFERROR(N34/N$32,"") | S34: =IFERROR(R34/R$32,"")
B35: Kantoor & informatica (612) | I35: =IFERROR(H35/H$32,"") | L35: =IFERROR(K35/K$32,"") | O35: =IFERROR(N35/N$32,"") | S35: =IFERROR(R35/R$32,"")
B36: Kosten wagenpark (613) | I36: =IFERROR(H36/H$32,"") | L36: =IFERROR(K36/K$32,"") | O36: =IFERROR(N36/N$32,"") | S36: =IFERROR(R36/R$32,"")
B37: Marketing (614) | I37: =IFERROR(H37/H$32,"") | L37: =IFERROR(K37/K$32,"") | O37: =IFERROR(N37/N$32,"") | S37: =IFERROR(R37/R$32,"")
B38: Overige (615) | I38: =IFERROR(H38/H$32,"") | L38: =IFERROR(K38/K$32,"") | O38: =IFERROR(N38/N$32,"") | S38: =IFERROR(R38/R$32,"")
B39: Bezoldiging bedrijfsleiders | I39: =IFERROR(H39/H$32,"") | L39: =IFERROR(K39/K$32,"") | O39: =IFERROR(N39/N$32,"") | S39: =IFERROR(R39/R$32,"")
B41: - Personeelskosten (incl. interims) | I41: =IFERROR(H41/H$12,"") | L41: =IFERROR(K41/K$12,"") | O41: =IFERROR(N41/N$12,"") | S41: =IFERROR(R41/R$12,"")
B43: + Overige bedrijfsopbrengsten | I43: =IFERROR(H43/H$12,"") | L43: =IFERROR(K43/K$12,"") | O43: =IFERROR(N43/N$12,"") | S43: =IFERROR(R43/R$12,"")
B45: - Overige bedrijfskosten | I45: =IFERROR(H45/H$12,"") | L45: =IFERROR(K45/K$12,"") | O45: =IFERROR(N45/N$12,"") | S45: =IFERROR(R45/R$12,"")
B47: + Financiële operationele opbrengsten | I47: =IFERROR(H47/H$12,"") | L47: =IFERROR(K47/K$12,"") | O47: =IFERROR(N47/N$12,"") | S47: =IFERROR(R47/R$12,"")
B48: - Opbrengsten beschikbare waarden (6) | I48: =IFERROR(H48/H$12,"") | L48: =IFERROR(K48/K$12,"") | O48: =IFERROR(N48/N$12,"") | S48: =IFERROR(R48/R$12,"")
B49: - Financiële operationele kosten | I49: =IFERROR(H49/H$12,"") | L49: =IFERROR(K49/K$12,"") | O49: =IFERROR(N49/N$12,"") | S49: =IFERROR(R49/R$12,"")
B50: - Intresten op RC/net debt (5) | I50: =IFERROR(H50/H$12,"") | L50: =IFERROR(K50/K$12,"") | O50: =IFERROR(N50/N$12,"") | S50: =IFERROR(R50/R$12,"")
B52: - Normalisaties (operationeel) (1) | H52: =H90+H104+H115 -> 0 | I52: =IFERROR(H52/H$12,"") | K52: =K90+K104+K115 -> 0 | L52: =IFERROR(K52/K$12,"") | N52: =N90+N104+N115 -> 0 | O52: =IFERROR(N52/N$12,"") | R52: =R90+R104+R115 -> 0 | S52: =IFERROR(R52/R$12,"")
V53: controle | W53: controle | X53: controle
B54: = EBITDA | H54: =H30+H32+H41+H43+H45+H47+H49+H52 -> 0 | I54: =IFERROR(H54/H$12,"") | K54: =K30+K32+K41+K43+K45+K47+K49+K52 -> 0 | L54: =IFERROR(K54/K$12,"") | N54: =N30+N32+N41+N43+N45+N47+N49+N52 -> 0 | O54: =IFERROR(N54/N$12,"") | R54: =R30+R32+R41+R43+R45+R47+R49+R52 -> 0 | S54: =IFERROR(R54/R$12,"") | V54: =H54-H52-H49-H47 -> 0 | W54: =K54-K52-K49-K47 -> 0 | X54: =N54-N52-N49-N47 -> 0
B55: weerhouden EBITDA | K55: =ROUND(H54*H74+K54*K74+N54*N74+R54*R74,-3) -> 0
...

Sheet OLO
A1: ='Gecorrigeerde vrije cash flow'!B1 -> [NAAM VENNOOTSCHAP]
A4: Berekeningstabel inflatievoet en OLO
A7: Bron:
A9: - Inflatie (historisch) : | C9: https://nl.inflation.eu/inflatiecijfers/belgie/historische-inflatie/cpi-inflatie-
C10: belgie.aspx
A11: - Inflatie (toekomst) : | C11: https://www.plan.be/databases/17-nl-indexcijfer+der+consumptieprijzen
C12: +inflatievooruitzichten
A13: - OLO (historisch) : | C13: http://stat.nbb.be/Index.aspx?DataSetCode=IRTRCERT&lang=nl
A14: - OLO (toekomst) : | C14: geen gegevens beschikbaar
A16: Gegevens :
A18: Jaar | D18: Inflatie | F18: OLO rentevoet
F19: 10 jaar | G19: 20 jaar | H19: 30 jaar
A21: 24 | B21: 2001 | D21: 0.0247 | F21: 0.0511 | G21: 0.056 | H21: 0.0568
A22: 23 | B22: 2002 | D22: 0.0165 | F22: 0.0498 | G22: 0.0535 | H22: 0.0538
A23: 22 | B23: 2003 | D23: 0.0159 | F23: 0.0417 | G23: 0.0479
A24: 21 | B24: 2004 | D24: 0.021 | F24: 0.0413 | G24: 0.0464
A25: 20 | B25: 2005 | D25: 0.0278 | F25: 0.0342 | G25: 0.0374 | H25: 0.039
A26: 19 | B26: 2006 | D26: 0.0179 | F26: 0.038 | G26: 0.0399 | H26: 0.0406
A27: 18 | B27: 2007 | D27: 0.0182 | F27: 0.0435 | G27: 0.0449 | H27: 0.0453
A28: 17 | B28: 2008 | D28: 0.0449 | F28: 0.0444 | G28: 0.0473 | H28: 0.0476
A29: 16 | B29: 2009 | D29: -0.0004 | F29: 0.0394 | G29: 0.0446 | H29: 0.0453
A30: 15 | B30: 2010 | D30: 0.0219 | F30: 0.0344 | G30: 0.0395 | H30: 0.0409
A31: 14 | B31: 2011 | D31: 0.0353 | F31: 0.042 | G31: 0.0458 | H31: 0.0467
A32: 13 | B32: 2012 | D32: 0.0284 | F32: 0.0298 | G32: 0.0358 | H32: 0.0366
A33: 12 | B33: 2013 | D33: 0.0111 | F33: 0.0243 | G33: 0.0318 | H33: 0.0337
A34: 11 | B34: 2014 | D34: 0.0034 | F34: 0.0172 | G34: 0.0247 | H34: 0.0275
A35: 10 | B35: 2015 | D35: 0.0056 | F35: 0.0086 | G35: 0.0152 | H35: 0.0169
A36: 9 | B36: 2016 | D36: 0.0197 | F36: 0.0049 | G36: 0.0114 | H36: 0.0142
... A44: 1 | B44: 2024 | D44: 0.0314 | F44: 0.0291 | G44: 0.0337 | H44: 0.0345
A45: 0 | B45: 2025 | D45: 0.0255 | G45: 0.0386
A47: Gemiddelde laatste 10 jaar | D47: =AVERAGE(D36:D45) -> 0.03015 | F47: =AVERAGE(F35:F44) -> 0.0107 | G47: =AVERAGE(G36:G45) -> 0.01843 | H47: =AVERAGE(H35:H44) -> 0.01818
A48: Gemiddelde laatste 10 jaar + T | D48: =AVERAGE(D35:D45) -> 0.027918182
A49: Gemiddelde laatste 20 jaar | D49: =AVERAGE(D26:D45) -> 0.02439 | F49: =AVERAGE(F25:F44) -> 0.02271 | G49: =AVERAGE(G26:G45) -> 0.02769 | H49: =AVERAGE(H25:H44) -> 0.02925
A50: Gemiddelde laatste 20 jaar + T | D50: =AVERAGE(D25:D45) -> 0.024552381

Sheet Rendementswaarde
A1: ='Gecorrigeerde vrije cash flow'!B1 -> [NAAM VENNOOTSCHAP]
A4: ='gecorrigeerd eigen vermogen'!A4 -> Toestand op [afsluitdatum] (afsluitdatum)
A7: RENDEMENTSWAARDE
A9: (gemiddelde van methode 1 en methode 2)
A12: rendementswaarde methode 1 | C12: ='rendementswaarde 1'!C19 -> 0
A13: rendementswaarde methode 2 | C13: ='rendementswaarde 2'!G44 -> 0
A15: rendementswaarde | C15: =ROUNDUP((C12+C13)/2,-4) -> 0

Sheet rendementswaarde 1
A1: =Rendementswaarde!A1 -> [NAAM VENNOOTSCHAP]
A4: ='gecorrigeerd eigen vermogen'!A4 -> Toestand op [afsluitdatum] (afsluitdatum)
A7: RENDEMENTSWAARDE METHODE 1
A10: gecorrigeerde vrije cash flow | C10: ='Gecorrigeerde vrije cash flow'!K76 -> 0
A11: rendementseis op geïnvesteerd vermogen | C11: =Goodwill!C16+4% -> 0.04 | F11: =IFERROR(C13/C10,0) -> 0 | G11: equity multiple
A12: (cf. berekening goodwill + 4% risicopremie)
C13: =C10/C11 -> 0
A15: + overtollig vermogen | C15: =Goodwill!E42 -> 0
A18: rendementswaarde | C18: =+C13+C15 -> 0
A19: afgerond | C19: =ROUNDUP(C18,-3) -> 0

Sheet rendementswaarde 2
A1: ='rendementswaarde 1'!A1 -> [NAAM VENNOOTSCHAP]
A4: ='gecorrigeerd eigen vermogen'!A4 -> Toestand op [afsluitdatum] (afsluitdatum)
A7: RENDEMENTSWAARDE METHODE 2
A10: genormaliseerde vrije cash flow | E10: ='Gecorrigeerde vrije cash flow'!K76 -> 0
A12: Terugverdienperiode | E12: 7 | F12: jaar
B14: vrije cash flow vóór belastingen | E14: ='Gecorrigeerde vrije cash flow'!K68 -> 0
B15: normale interest voor financiering | E15: =Goodwill!C18-1% -> 0.03269 | F15: (OLO 20jaar)
B16: te ontlenen kapitaal met cash flow | E16: =G29 -> 0
B17: afgerond | E17: =ROUND((1-$F$20)*E12*E14/(1+(1-$F$20)*E15*E12/2),2) -> 0 | F17: EUR
C19: kapitaal | D19: interest | E19: winst voor | F19: belasting | G19: winst na
E20: belasting | F20: 0.25 | G20: belasting
B22: jaar 1 | C22: =E17 -> 0 | D22: =(C22+C23)/2*$E$15 -> 0 | E22: =$E$14-D22 -> 0 | F22: =-E22*25% -> 0 | G22: =E22+F22 -> 0
B23: jaar 2 | C23: =C22-$C$22/$E$12 -> 0 | D23: =(C23+C24)/2*$E$15 -> 0 | E23: =$E$14-D23 -> 0 | F23: =-E23*25% -> 0 | G23: =E23+F23 -> 0
B24: jaar 3 | C24: =C23-$C$22/$E$12 -> 0 | D24: =(C24+C25)/2*$E$15 -> 0 | E24: =$E$14-D24 -> 0 | F24: =-E24*25% -> 0 | G24: =E24+F24 -> 0
B25: jaar 4 | C25: =C24-$C$22/$E$12 -> 0 | D25: =(C25+C26)/2*$E$15 -> 0 | E25: =$E$14-D25 -> 0 | F25: =-E25*25% -> 0 | G25: =E25+F25 -> 0
B26: jaar 5 | C26: =C25-$C$22/$E$12 -> 0 | D26: =(C26+C27)/2*$E$15 -> 0 | E26: =$E$14-D26 -> 0 | F26: =-E26*25% -> 0 | G26: =E26+F26 -> 0
B27: jaar 6 | C27: =C26-$C$22/$E$12 -> 0 | D27: =(C27+C28)/2*$E$15 -> 0 | E27: =$E$14-D27 -> 0 | F27: =-E27*25% -> 0 | G27: =E27+F27 -> 0
B28: jaar 7 | C28: =C27-$C$22/$E$12 -> 0 | D28: =(C28+C29)/2*$E$15 -> 0 | E28: =$E$14-D28 -> 0 | F28: =-E28*25% -> 0 | G28: =E28+F28 -> 0
G29: =SUM(G22:G28) -> 0
B31: gecorrigeerd eigen vermogen | E31: =ROUND('gecorrigeerd eigen vermogen'!E44,-3) -> 0
B32: sociaal passief (1) | E32: 0
B33: extra liquidatiebelasting | E33: 0
B34: vennootschapsbelasting (25 %) | E34: =-(25%-'gecorrigeerd eigen vermogen'!C26)*'gecorrigeerd eigen vermogen'!D25 -> 0
B35: liquidatiebelasting (0%) | E35: =(-'gecorrigeerd eigen vermogen'!D38*0%)-'gecorrigeerd eigen vermogen'!E33 -> 0
E36: =SUM(E31:E35) -> 0
B37: actualisatievoet (2) | E37: =J74 -> 0.04269
E38: =E36/((1+E37)^E12) -> 0
B40: te ontlenen kapitaal met cash flow | G40: =+E17 -> 0
B41: gecorrigeerd eigen vermogen bij onmiddellijke liquidatie | G41: =ROUND(E38,-3) -> 0
A43: rendementswaarde methode 2 | G43: =SUM(G40:G42) -> 0
A44: afgerond | G44: =ROUND(G43,-3) -> 0
A49: (1) Sociaal passief :
B51: Het betreft zowel bedienden als arbeiders. In het kader van de overgang naar het eenheidsstatuut
B52: wordt voor zowel de bedienden als de arbeiders rekening gehouden met een gemiddelde opzeg-
B53: termijn van 2 maand.
B55: Bezoldiging arbeiders + bedienden | D55: =-'Gecorrigeerde vrije cash flow'!N41 -> 0 | E55: code 620/621
B56: aantal maanden | D56: 1/6
B57: Sociaal passief | D57: =D55/6 -> 0
B58: Belastingsvoet | D58: 0.25
B59: Weerhouden sociaal passief | D59: =D57*(1-D58) -> 0
...

Sheet Marktwaarde 
A1: ='rendementswaarde 2'!A1 -> [NAAM VENNOOTSCHAP]
A4: ='weerhouden waarde'!A6 -> Toestand op [afsluitdatum] (afsluitdatum)
A7: MARKTWAARDE OBV EBITDA
B10: Waarde | C10: Weging | D10: Weerhouden
A12: =IF('Gecorrigeerde vrije cash flow'!R9="","EBITDA boekjaar","EBITDA boekjaar "&YEAR('Gecorrigeerde vrije cash flow'!R9)&" (prognose)") -> EBITDA boekjaar | B12: ='Gecorrigeerde vrije cash flow'!R54 -> 0 | C12: ='Gecorrigeerde vrije cash flow'!R74 -> 0 | D12: =B12*C12 -> 0
A13: =IF('Gecorrigeerde vrije cash flow'!N9="","EBITDA boekjaar","EBITDA boekjaar "&YEAR('Gecorrigeerde vrije cash flow'!N9)&"") -> EBITDA boekjaar | B13: ='Gecorrigeerde vrije cash flow'!N54 -> 0 | C13: ='Gecorrigeerde vrije cash flow'!N74 -> 0 | D13: =B13*C13 -> 0
A14: =IF('Gecorrigeerde vrije cash flow'!K9="","EBITDA boekjaar","EBITDA boekjaar "&YEAR('Gecorrigeerde vrije cash flow'!K9)&"") -> EBITDA boekjaar | B14: ='Gecorrigeerde vrije cash flow'!K54 -> 0 | C14: ='Gecorrigeerde vrije cash flow'!K74 -> 0 | D14: =B14*C14 -> 0
A15: =IF('Gecorrigeerde vrije cash flow'!H9="","EBITDA boekjaar","EBITDA boekjaar "&YEAR('Gecorrigeerde vrije cash flow'!H9)&"") -> EBITDA boekjaar | B15: ='Gecorrigeerde vrije cash flow'!H54 -> 0 | C15: ='Gecorrigeerde vrije cash flow'!H74 -> 0 | D15: =B15*C15 -> 0
A17: Gewogen gemiddelde EBITDA (afgerond) | D17: =ROUND(SUM(D12:D15),-2) -> 0
A19: Weerhouden multiplicator obv VLERICK M&A Monitor [jaar] ([sector])
A21: Ondernemingswaarde | D21: =D17*D19 -> 0
A23: + aanvullende activa (cash + RC) / - net debt | D23: =Goodwill!E42 -> 0
A24: - debt (1) | D24: =-Goodwill!C83 -> 0
A26: Marktwaarde obv EBITDA | D26: =+D21+D23+D24 -> 0
A27: afgerond | D27: =ROUND(D26,-3) -> 0
